Workbook

Sheet 📋 Documentation
A1: LIIMRA NATURALS — UNIT ECONOMICS MODEL | FY 2026-27
A2: Model Documentation, Methodology & Glossary
A4: PURPOSE
A5: Scope | B5: This workbook models SKU-level unit economics for Liimra Naturals' Flipkart marketplace business for FY 2026-27. It is built on FY 2024-25 actuals (COGS, return rates, per-unit OpEx) layered with new selling prices and a +20% volume growth assumption.
A6: Sheets in this workbook | B6: 📋 Documentation | 📊 FY2627 Actuals | 🎛 What-If Model | 🏪 Marketplace UE
A8: MODEL ASSUMPTIONS
A9: Volume growth | B9: +20% on FY 2024-25 gross units ordered, rounded to whole units (blue hardcoded inputs)
A10: Selling prices | B10: Updated selling prices sourced from sku.xlsx (10 SKUs updated; remainder carried forward)
A11: COGS | B11: Carried forward from FY 2024-25 actuals — includes product cost + packing material
A12: Return rate | B12: 8.00% flat across all SKUs (FY 2024-25 observed rate)
A13: Ad spend | B13: ₹17,702 total held constant at FY 2024-25 level; allocated pro-rata by SKU net revenue share
A14: Fixed overheads | B14: ₹30,000/month (Warehousing ₹10k + Salary ₹15k + Misc ₹5k) = ₹3,60,000/year
A15: TCS | B15: 1% of Net Selling Price (collected by Flipkart, remittable on filing)
A16: TDS | B16: 0.1% of Net Revenue (deducted by Flipkart, recoverable against advance tax)
A17: GST on MP fees | B17: 18% on Flipkart fixed fee + collection fee
A19: METRIC DEFINITIONS
A20: Gross Units Ordered | B20: Total orders placed by customers before returns
A21: Net Units Sold | B21: Gross Units − Returns
A22: Net Selling Price (NSP) | B22: Listing price net of customer returns. Equals listing price since return-adjusted.
A23: Gross Revenue | B23: Gross Units × Listing Price
A24: Net Revenue | B24: Gross Revenue − Returns & Refunds value
A25: COGS incl. Packing | B25: Direct product cost + packing per unit, carried from actuals
A26: Gross Profit | B26: Net Revenue − Total COGS
A27: Gross Margin % | B27: Gross Profit ÷ Net Revenue
A28: Marketplace Fees | B28: Flipkart fixed fee per unit (weight/category-based) + collection fee
A29: Logistics — Returns | B29: Reverse shipping cost per returned unit, allocated to net units
A30: Ad Spend Allocated | B30: SKU's share of total ad spend, pro-rated by net revenue
A31: TCS | B31: Tax Collected at Source: 1% of NSP, collected by Flipkart, remitted by seller to tax dept
... A43: Net Profit after Fixed OH | B43: Net Profit − Fixed Overhead Allocated
A45: COLOUR CODING
A46: Blue text | B46: Hardcoded input values (do not overwrite with formulas)
A47: Black text | B47: Formula-derived values
A48: Green text | B48: Cross-sheet links
A49: Yellow background | B49: Key assumption cells — review before running scenarios
A51: MARKETPLACE SHEET NOTES
A52: Purpose | B52: Standalone unit economics calculator for any marketplace (Flipkart, Amazon, JioMart, eBay). Enter the marketplace fee structure and product details to compute margins and BEP.
A53: Fee structures | B53: Amazon: Referral fee % + Closing fee + Weight handling; Flipkart: Fixed fee + Collection fee; JioMart/eBay: Commission %. All configured in the Marketplace UE sheet.
A55: WHAT-IF MODEL NOTES
A56: Purpose | B56: Sensitivity model — change price, volume, COGS, return rate, ad spend. All outputs auto-recalculate.
A57: Scenario toggle | B57: Choose Base / Bull / Bear scenario from dropdown. Each has its own assumption set.
...

Sheet ⚙ Config & Assumptions
A1: LIIMRA NATURALS | CONFIGURABLE ASSUMPTIONS REGISTER | FY 2026-27
A2: All BLUE cells are configurable inputs. Change them here and all linked sheets update automatically. Black = formula-derived. Yellow background = high-impact assumption — review before publishing.
A3: Parameter | B3: Current Value | C3: Allowed Range / Notes | D3: Impact & Description
A4: ◆ VOLUME & GROWTH
A5: Annual Gross Units Ordered (FY Plan) | B5: 1123 | C5: 500 – 5000 | D5: Total orders placed before returns. Drives all revenue & cost lines. +20% vs FY24-25.
A6: Volume Growth Rate vs Prior Year (%) | B6: 0.2 | C6: 0% – 100% | D6: Year-on-year gross unit growth assumption. Currently set to 20%.
A7: Monthly Seasonality — April | B7: 0.07 | C7: 0.01 – 0.20 | D7: Share of annual volume in April. All 12 months must sum to 1.0.
A8: Monthly Seasonality — May | B8: 0.075 | C8: 0.01 – 0.20 | D8: Share of annual volume in May.
A9: Monthly Seasonality — June | B9: 0.065 | C9: 0.01 – 0.20 | D9: Share of annual volume in June.
A10: Monthly Seasonality — July | B10: 0.075 | C10: 0.01 – 0.20 | D10: Share of annual volume in July.
A11: Monthly Seasonality — August | B11: 0.09 | C11: 0.01 – 0.20 | D11: Festive ramp-up begins. Raksha Bandhan / Independence Day spike.
A12: Monthly Seasonality — September | B12: 0.095 | C12: 0.01 – 0.20 | D12: Navratri / Onam. Peak health-food demand.
A13: Monthly Seasonality — October | B13: 0.1 | C13: 0.01 – 0.20 | D13: Dussehra / Dhanteras. Highest month — gifting + wellness spend.
A14: Monthly Seasonality — November | B14: 0.095 | C14: 0.01 – 0.20 | D14: Diwali / post-festive. Still elevated.
A15: Monthly Seasonality — December | B15: 0.09 | C15: 0.01 – 0.20 | D15: Year-end / Christmas. Moderate.
A16: Monthly Seasonality — January | B16: 0.09 | C16: 0.01 – 0.20 | D16: New Year resolution health wave.
... A18: Monthly Seasonality — March | B18: 0.07 | C18: 0.01 – 0.20 | D18: Year-end slowdown before new FY.
A19: Seasonality Sum (must = 1.00) | B19: =SUM(B6:B17) -> 1.13 | C19: Must equal 1.00 | D19: Auto-checks. If not 1.00, monthly plans will not match annual total.
A20: ◆ PRICING & RETURNS
A21: Blended Average NSP (₹/unit) | B21: 155.64 | C21: 100 – 300 | D21: Weighted average net selling price across all SKUs. Update if mix shifts.
A22: Return Rate — Blended (%) | B22: 0.0793 | C22: 0% – 20% | D22: FY24-25 observed blended return rate (7.93%). Changes here flow through to net units.
A23: ◆ COST STRUCTURE
A24: Blended COGS incl. Packing (₹/unit) | B24: 91.65 | C24: 60 – 150 | D24: Weighted average COGS. Update if product mix or input costs change.
A25: Blended Marketplace Fee (₹/unit) | B25: 9.06 | C25: 7 – 15 | D25: Weighted avg FK fixed fee. Increases with heavier/higher-value SKUs.
A26: Blended Reverse Logistics (₹/net unit) | B26: 4.46 | C26: 0 – 25 | D26: Weighted avg reverse shipping cost. Allocated to net units sold.
A27: ◆ ADVERTISING
A28: Total Annual Ad Spend (₹) | B28: 17702 | C28: 5000 – 100000 | D28: Held constant from FY24-25. Increase to test volume uplift scenarios.
A29: Ad Spend Monthly Distribution | B29: Equal (1/12) | C29: Equal or seasonal | D29: Currently split equally across months. Can be made seasonal in Config sheet.
A30: ◆ TAXES & COMPLIANCE
A31: TCS Rate (%) | B31: 0.01 | C31: 1% (statutory) | D31: Tax Collected at Source by Flipkart. Statutory — do not change.
A32: TDS Rate (%) | B32: 0.001 | C32: 0.1% (statutory) | D32: Tax Deducted at Source by Flipkart. Recoverable. Statutory — do not change.
A33: GST on Marketplace Fees (%) | B33: 0.18 | C33: 18% (statutory) | D33: GST on platform fees paid by seller. Statutory — do not change.
A34: ◆ FIXED OVERHEADS
A35: Monthly Warehousing Cost (₹) | B35: 10000 | C35: 5000 – 50000 | D35: Current: single warehouse location. Update if storage needs expand.
A36: Monthly Salary Cost (₹) | B36: 15000 | C36: 10000 – 100000 | D36: Currently 1 FTE. Update on headcount addition.
A37: Monthly Miscellaneous (₹) | B37: 5000 | C37: 1000 – 20000 | D37: Packaging consumables, utilities, software subscriptions.
A38: Total Monthly Fixed Overheads (₹) | B38: =B31+B32+B33 -> 0.191 | C38: Target < ₹50,000/month | D38: Sum of above. ₹30,000/month = ₹3,60,000 annually.
A39: Total Annual Fixed Overheads (₹) | B39: =B34*12 -> 0 | C39: — | D39: Annualised. Allocated pro-rata by net revenue share across SKUs.
A40: ◆ PLAN VS ACTUAL
A41: Current Reporting Month (1=Apr … 12=Mar) | B41: 1 | C41: 1 – 12 | D41: Set this to current month number. Controls MTD & YTD calculations in PvA sheet.
...

Sheet 🏪 Marketplace UE
A1: LIIMRA NATURALS | MARKETPLACE-DRIVEN UNIT ECONOMICS | FY 2026-27
A2: Calculate and compare unit economics across Flipkart, Amazon India, JioMart & eBay India. Blue cells = inputs. Change any value to see live recalculation.
A4: Parameter / Metric | B4: Flipkart | C4: Amazon India | D4: JioMart | E4: eBay India
A5: ── PRODUCT (same across all platforms)
A6: MRP / Listing Price (₹/unit) | B6: 164 | C6: 164 | D6: 164 | E6: 164
A7: COGS incl. Packing (₹/unit) | B7: 92.35 | C7: 92.35 | D7: 92.35 | E7: 92.35
A8: Monthly Volume (Units, net sold) | B8: 66 | C8: 25 | D8: 15 | E8: 5
A9: Return Rate (%) | B9: 0.08 | C9: 0.12 | D9: 0.05 | E9: 0.03
A11: ── MARKETPLACE FEE STRUCTURE
A12: Referral / Commission (%) | B12: 0 | C12: 0.05 | D12: 0.06 | E12: 0.09
A13: Fixed Fee per Order (₹) | B13: 9 | C13: 0 | D13: 0 | E13: 0
A14: Closing / Weight Handling Fee (₹) | B14: 0 | C14: 25 | D14: 0 | E14: 0
A15: Shipping charged to seller (₹/unit) | B15: 0 | C15: 45 | D15: 0 | E15: 0
A16: Reverse Logistics per return (₹) | B16: 3.35 | C16: 55 | D16: 0 | E16: 0
A17: GST on platform fees (%) | B17: 0.18 | C17: 0.18 | D17: 0.18 | E17: 0
A19: ── TAXES
A20: TCS Rate (%) | B20: 0.01 | C20: 0.01 | D20: 0 | E20: 0
A21: TDS Rate (%) | B21: 0.001 | C21: 0.001 | D21: 0 | E21: 0
A23: ── ADVERTISING
A24: Monthly Ad Spend (₹) | B24: 1475 | C24: 800 | D24: 0 | E24: 0
A26: COMPUTED UNIT ECONOMICS (Monthly Basis)
A27: ── REVENUE (Monthly)
A28: Gross Units | B28: =ROUND(B8/(1-B9),0) -> 72 | C28: =ROUND(C8/(1-C9),0) -> 28 | D28: =ROUND(D8/(1-D9),0) -> 16 | E28: =ROUND(E8/(1-E9),0) -> 5
A29: Net Units Sold | B29: =B8 -> 66 | C29: =C8 -> 25 | D29: =D8 -> 15 | E29: =E8 -> 5
A30: Gross Revenue (₹) | B30: =ROUND(B8/(1-B9)*B6,0) -> 11765 | C30: =ROUND(C8/(1-C9)*C6,0) -> 4659 | D30: =ROUND(D8/(1-D9)*D6,0) -> 2589 | E30: =ROUND(E8/(1-E9)*E6,0) -> 845
A31: Refund Value (₹) | B31: =ROUND((B8/(1-B9)-B8)*B6,0) -> 941 | C31: =ROUND((C8/(1-C9)-C8)*C6,0) -> 559 | D31: =ROUND((D8/(1-D9)-D8)*D6,0) -> 129 | E31: =ROUND((E8/(1-E9)-E8)*E6,0) -> 25
A32: Net Revenue (₹) | B32: =B8*B6 -> 10824 | C32: =C8*C6 -> 4100 | D32: =D8*D6 -> 2460 | E32: =E8*E6 -> 820
A34: ── COSTS (Monthly)
A35: COGS Total (₹) | B35: =B8*B7 -> 6095.1 | C35: =C8*C7 -> 2308.75 | D35: =D8*D7 -> 1385.25 | E35: =E8*E7 -> 461.75
A36: Platform Commission (₹) | B36: =ROUND(B8*B6*B12,0) -> 0 | C36: =ROUND(C8*C6*C12,0) -> 205 | D36: =ROUND(D8*D6*D12,0) -> 148 | E36: =ROUND(E8*E6*E12,0) -> 74
A37: Fixed Fee Total (₹) | B37: =B8*B13 -> 594 | C37: =C8*C13 -> 0 | D37: =D8*D13 -> 0 | E37: =E8*E13 -> 0
A38: Closing / Weight Handling (₹) | B38: =B8*B14 -> 0 | C38: =C8*C14 -> 625 | D38: =D8*D14 -> 0 | E38: =E8*E14 -> 0
A39: Outbound Shipping (₹) | B39: =B8*B15 -> 0 | C39: =C8*C15 -> 1125 | D39: =D8*D15 -> 0 | E39: =E8*E15 -> 0
A40: Reverse Logistics (₹) | B40: =ROUND((B8/(1-B9)-B8)*B16,0) -> 19 | C40: =ROUND((C8/(1-C9)-C8)*C16,0) -> 188 | D40: =ROUND((D8/(1-D9)-D8)*D16,0) -> 0 | E40: =ROUND((E8/(1-E9)-E8)*E16,0) -> 0
A41: GST on Platform Fees (₹) | B41: =ROUND((B8*B6*B12+B8*B13+B8*B14)*B17,0) -> 107 | C41: =ROUND((C8*C6*C12+C8*C13+C8*C14)*C17,0) -> 149 | D41: =ROUND((D8*D6*D12+D8*D13+D8*D14)*D17,0) -> 27 | E41: =ROUND((E8*E6*E12+E8*E13+E8*E14)*E17,0) -> 0
A42: TCS (₹) | B42: =ROUND(B8*B6*B20,0) -> 108 | C42: =ROUND(C8*C6*C20,0) -> 41 | D42: =ROUND(D8*D6*D20,0) -> 0 | E42: =ROUND(E8*E6*E20,0) -> 0
A43: TDS (₹) [recoverable] | B43: =ROUND(B8*B6*B21,0) -> 11 | C43: =ROUND(C8*C6*C21,0) -> 4 | D43: =ROUND(D8*D6*D21,0) -> 0 | E43: =ROUND(E8*E6*E21,0) -> 0
A44: Ad Spend (₹) | B44: =B24 -> 1475 | C44: =C24 -> 800 | D44: =D24 -> 0 | E44: =E24 -> 0
A46: ── P&L SUMMARY (Monthly)
A47: Gross Profit (₹) | B47: =B32-B35 -> 4728.9 | C47: =C32-C35 -> 1791.25 | D47: =D32-D35 -> 1074.75 | E47: =E32-E35 -> 358.25
...

Sheet 🎛 What-If Model
A1: LIIMRA NATURALS | WHAT-IF SCENARIO MODEL | FY 2026-27
A2: Adjust assumptions in the BLUE cells. All metrics auto-recalculate. Three scenario columns: Base (actuals) | Bull (+) | Bear (−)
A4: Assumption | B4: Base Case (FY2627 Plan) | C4: Bull Case (Upside) | D4: Bear Case (Downside)
A5: ── VOLUME & PRICE
A6: Annual Gross Units | B6: 1123 | C6: 1400 | D6: 850
A7: Return Rate (%) | B7: 0.08 | C7: 0.06 | D7: 0.12
A8: Avg Net Selling Price (₹/unit) | B8: 155.64 | C8: 170 | D8: 140
A10: ── COST STRUCTURE
A11: Avg COGS incl. Packing (₹/unit) | B11: 91.65 | C11: 88 | D11: 95
A12: Avg Marketplace Fee (₹/unit) | B12: 9.06 | C12: 9.06 | D12: 10
A13: Avg Reverse Logistics (₹/unit) | B13: 4.46 | C13: 3.5 | D13: 6
A15: ── ADVERTISING
A16: Total Ad Spend (₹) | B16: 17702 | C16: 17702 | D16: 22000
A18: ── TAXES & COMPLIANCE
A19: TCS Rate (%) | B19: 0.01 | C19: 0.01 | D19: 0.01
A20: GST on MP Fees Rate (%) | B20: 0.18 | C20: 0.18 | D20: 0.18
A21: TDS Rate (%) | B21: 0.001 | C21: 0.001 | D21: 0.001
A23: ── FIXED OVERHEADS
A24: Annual Fixed Overheads (₹) | B24: 360000 | C24: 360000 | D24: 420000
A26: COMPUTED OUTPUTS — all values in ₹ unless stated
A27: Metric | B27: Base Case | C27: Bull Case | D27: Bear Case
A28: ── VOLUME
A29: Net Units Sold | B29: =ROUND(B6*(1-B7),0) -> 1033 | C29: =ROUND(C6*(1-C7),0) -> 1316 | D29: =ROUND(D6*(1-D7),0) -> 748
A30: Returns (Units) | B30: =ROUND(B6*B7,0) -> 90 | C30: =ROUND(C6*C7,0) -> 84 | D30: =ROUND(D6*D7,0) -> 102
A32: ── REVENUE
A33: Gross Revenue (₹) | B33: =B6*B8 -> 174783.72 | C33: =C6*C8 -> 238000 | D33: =D6*D8 -> 119000
A34: Net Revenue (₹) | B34: =ROUND(B6*(1-B7)*B8,0) -> 160801 | C34: =ROUND(C6*(1-C7)*C8,0) -> 223720 | D34: =ROUND(D6*(1-D7)*D8,0) -> 104720
A36: ── COST & PROFIT
A37: Total COGS (₹) | B37: =ROUND(B6*(1-B7)*B11,0) -> 94689 | C37: =ROUND(C6*(1-C7)*C11,0) -> 115808 | D37: =ROUND(D6*(1-D7)*D11,0) -> 71060
A38: Gross Profit (₹) | B38: =ROUND(B6*(1-B7)*B8,0)-ROUND(B6*(1-B7)*B11,0) -> 66112 | C38: =ROUND(C6*(1-C7)*C8,0)-ROUND(C6*(1-C7)*C11,0) -> 107912 | D38: =ROUND(D6*(1-D7)*D8,0)-ROUND(D6*(1-D7)*D11,0) -> 33660
A39: Gross Margin (%) | B39: =(ROUND(B6*(1-B7)*B8,0)-ROUND(B6*(1-B7)*B11,0))/ROUND(B6*(1-B7)*B8,0) -> 0.41114172 | C39: =(ROUND(C6*(1-C7)*C8,0)-ROUND(C6*(1-C7)*C11,0))/ROUND(C6*(1-C7)*C8,0) -> 0.48235294 | D39: =(ROUND(D6*(1-D7)*D8,0)-ROUND(D6*(1-D7)*D11,0))/ROUND(D6*(1-D7)*D8,0) -> 0.32142857
A41: ── OPERATING EXPENSES
A42: Total Marketplace Fees (₹) | B42: =ROUND(B6*(1-B7)*B12,0) -> 9360 | C42: =ROUND(C6*(1-C7)*C12,0) -> 11923 | D42: =ROUND(D6*(1-D7)*D12,0) -> 7480
A43: Total Logistics (₹) | B43: =ROUND(B6*(1-B7)*B13,0) -> 4608 | C43: =ROUND(C6*(1-C7)*C13,0) -> 4606 | D43: =ROUND(D6*(1-D7)*D13,0) -> 4488
A44: Ad Spend (₹) | B44: =B16 -> 17702 | C44: =C16 -> 17702 | D44: =D16 -> 22000
A45: Total Taxes — TCS+GST (₹) | B45: =ROUND(B6*(1-B7)*(B8*B19+B12*B20),0) -> 3293 | C45: =ROUND(C6*(1-C7)*(C8*C19+C12*C20),0) -> 4383 | D45: =ROUND(D6*(1-D7)*(D8*D19+D12*D20),0) -> 2394
A47: ── BOTTOM LINE
A48: Operating Profit (₹) | B48: =ROUND(B6*(1-B7)*B8,0)-ROUND(B6*(1-B7)*B11,0)-ROUND(B6*(1-B7)*B12,0)-ROUND(B6*(1-B7)*B13,0)-B16-ROUND(B6*(1-B7)*(B8*B19+B12*B20),0) -> 31149 | C48: =ROUND(C6*(1-C7)*C8,0)-ROUND(C6*(1-C7)*C11,0)-ROUND(C6*(1-C7)*C12,0)-ROUND(C6*(1-C7)*C13,0)-C16-ROUND(C6*(1-C7)*(C8*C19+C12*C20),0) -> 69298 | D48: =ROUND(D6*(1-D7)*D8,0)-ROUND(D6*(1-D7)*D11,0)-ROUND(D6*(1-D7)*D12,0)-ROUND(D6*(1-D7)*D13,0)-D16-ROUND(D6*(1-D7)*(D8*D19+D12*D20),0) -> -2702
A49: Operating Margin (%) | B49: =IF(B34=0,0,B48/B34) -> 0.19371148 | C49: =IF(C34=0,0,C48/C34) -> 0.30975326 | D49: =IF(D34=0,0,D48/D34) -> -0.025802139
A50: TDS (₹) [recoverable] | B50: =ROUND(B6*(1-B7)*B8*B21,0) -> 161 | C50: =ROUND(C6*(1-C7)*C8*C21,0) -> 224 | D50: =ROUND(D6*(1-D7)*D8*D21,0) -> 105
...

Sheet 📊 FY2627 Actuals
A1: LIIMRA NATURALS | FY 2026-27 | SKU-wise Unit Economics (Projected)
A2: Blue = hardcoded inputs · Black = formulas · Green = cross-sheet links · COGS & per-unit OpEx rates from FY24-25 actuals · Ad Spend total held constant · Gross Units +20%
A4: Section | B4: Metric | C4: Combo 250×3 | D4: Combo 250×6 | E4: Ragi 250g | F4: Bajra 250g | G4: Jowar 250g | H4: Kagni 250g | I4: Kutki 250g | J4: Kodo 250g | K4: Ragi 500g | L4: Jowar 500g | M4: Bajra 500g | N4: Kangni 500g | O4: Kutki 500g | P4: Kodo 500g | Q4: Ragi 1kg | R4: Jowar 1kg | S4: Bajra 1kg | T4: Indrayani | U4: Total / Wtd Avg
A6: ① VOLUME (Full Year Units)
A7: ① Volume | B7: Gross Units Ordered | C7: 868 | D7: 61 | E7: 1 | F7: 1 | G7: 1 | H7: 1 | I7: 1 | J7: 1 | K7: 53 | L7: 16 | M7: 4 | N7: 20 | O7: 7 | P7: 1 | Q7: 1 | R7: 8 | S7: 77 | T7: 1 | U7: 1123
B8: Return Rate (%) | C8: 0.08 | D8: 0.08 | E8: 0.08 | F8: 0.08 | G8: 0.08 | H8: 0.08 | I8: 0.08 | J8: 0.08 | K8: 0.08 | L8: 0.08 | M8: 0.08 | N8: 0.08 | O8: 0.08 | P8: 0.08 | Q8: 0.08 | R8: 0.08 | S8: 0.08 | T8: 0.08 | U8: 0.079252004
B9: Returns (Units) | C9: 69 | D9: 5 | E9: 0 | F9: 0 | G9: 0 | H9: 0 | I9: 0 | J9: 0 | K9: 4 | L9: 1 | M9: 0 | N9: 2 | O9: 1 | P9: 0 | Q9: 0 | R9: 1 | S9: 6 | T9: 0 | U9: 89
B10: Net Units Sold | C10: 799 | D10: 56 | E10: 1 | F10: 1 | G10: 1 | H10: 1 | I10: 1 | J10: 1 | K10: 49 | L10: 15 | M10: 4 | N10: 18 | O10: 6 | P10: 1 | Q10: 1 | R10: 7 | S10: 71 | T10: 1 | U10: 1034
A11: ② REVENUE
A12: ② Revenue | B12: New Selling Price (₹/unit) | C12: 164 | D12: 250 | E12: 87 | F12: 78 | G12: 85 | H12: 71 | I12: 83 | J12: 85 | K12: 71 | L12: 70 | M12: 71 | N12: 88 | O12: 108 | P12: 130 | Q12: 110 | R12: 105 | S12: 102 | T12: 168
B13: Gross Revenue (₹) | C13: 142352 | D13: 15250 | E13: 87 | F13: 78 | G13: 85 | H13: 71 | I13: 83 | J13: 85 | K13: 3763 | L13: 1120 | M13: 284 | N13: 1760 | O13: 756 | P13: 130 | Q13: 110 | R13: 840 | S13: 7854 | T13: 168 | U13: 174876
B14: (−) Returns & Refunds (₹) | C14: 11316 | D14: 1250 | E14: 0 | F14: 0 | G14: 0 | H14: 0 | I14: 0 | J14: 0 | K14: 284 | L14: 70 | M14: 0 | N14: 176 | O14: 108 | P14: 0 | Q14: 0 | R14: 105 | S14: 612 | T14: 0 | U14: 13921
B15: Net Revenue (₹) | C15: 131036 | D15: 14000 | E15: 87 | F15: 78 | G15: 85 | H15: 71 | I15: 83 | J15: 85 | K15: 3479 | L15: 1050 | M15: 284 | N15: 1584 | O15: 648 | P15: 130 | Q15: 110 | R15: 735 | S15: 7242 | T15: 168 | U15: 160955
B16: Net Selling Price (₹/net unit) | C16: 164 | D16: 250 | E16: 87 | F16: 78 | G16: 85 | H16: 71 | I16: 83 | J16: 85 | K16: 71 | L16: 70 | M16: 71 | N16: 88 | O16: 108 | P16: 130 | Q16: 110 | R16: 105 | S16: 102 | T16: 168 | U16: 155.66
A17: ③ COST OF GOODS SOLD
A18: ③ COGS | B18: COGS incl. Packing (₹/unit) | C18: 92.35 | D18: 184.7 | E18: 32.5 | F18: 29.4 | G18: 30.44 | H18: 31.2 | I18: 32.5 | J18: 46.92 | K18: 49.99 | L18: 45.87 | M18: 43.81 | N18: 47.42 | O18: 49.99 | P18: 94 | Q18: 84.98 | R18: 76.74 | S18: 72.62 | T18: 87
B19: Total COGS (₹) | C19: 73787.65 | D19: 10343.2 | E19: 32.5 | F19: 29.4 | G19: 30.44 | H19: 31.2 | I19: 32.5 | J19: 46.92 | K19: 2449.51 | L19: 688.05 | M19: 175.24 | N19: 853.56 | O19: 299.94 | P19: 94 | Q19: 84.98 | R19: 537.18 | S19: 5156.02 | T19: 87 | U19: 94759.29
A20: ④ GROSS PROFIT
A21: ④ GP | B21: Gross Profit (₹) | C21: 57248.35 | D21: 3656.8 | E21: 54.5 | F21: 48.6 | G21: 54.56 | H21: 39.8 | I21: 50.5 | J21: 38.08 | K21: 1029.49 | L21: 361.95 | M21: 108.76 | N21: 730.44 | O21: 348.06 | P21: 36 | Q21: 25.02 | R21: 197.82 | S21: 2085.98 | T21: 81 | U21: 66195.71
B22: Gross Profit per Net Unit (₹) | C22: 71.65 | D22: 65.3 | E22: 54.5 | F22: 48.6 | G22: 54.56 | H22: 39.8 | I22: 50.5 | J22: 38.08 | K22: 21.01 | L22: 24.13 | M22: 27.19 | N22: 40.58 | O22: 58.01 | P22: 36 | Q22: 25.02 | R22: 28.26 | S22: 29.38 | T22: 81 | U22: 64.02
B23: Gross Margin (%) | C23: 0.437 | D23: 0.261 | E23: 0.626 | F23: 0.623 | G23: 0.642 | H23: 0.561 | I23: 0.608 | J23: 0.448 | K23: 0.296 | L23: 0.345 | M23: 0.383 | N23: 0.461 | O23: 0.537 | P23: 0.277 | Q23: 0.227 | R23: 0.269 | S23: 0.288 | T23: 0.482 | U23: 0.411
A24: ⑤ OPERATING EXPENSES
A25: ⑤ OpEx | B25: FK Fixed Fee (₹/net unit) | C25: 9 | D25: 12 | E25: 7 | F25: 7 | G25: 7 | H25: 7 | I25: 7 | J25: 7 | K25: 8 | L25: 8 | M25: 7 | N25: 8 | O25: 9 | P25: 8 | Q25: 8 | R25: 9 | S25: 9 | T25: 9
B26: Total Marketplace Fees (₹) | C26: 7191 | D26: 672 | E26: 7 | F26: 7 | G26: 7 | H26: 7 | I26: 7 | J26: 7 | K26: 392 | L26: 120 | M26: 28 | N26: 144 | O26: 54 | P26: 8 | Q26: 8 | R26: 63 | S26: 639 | T26: 9 | U26: 9370
B27: Reverse Shipping (₹/net unit) | C27: 3.35 | D27: 22.46 | E27: 12.29 | F27: 12.29 | G27: 12.29 | H27: 12.29 | I27: 12.29 | J27: 12.29 | K27: 12.29 | L27: 0 | M27: 0 | N27: 0 | O27: 0 | P27: 0 | Q27: 0 | R27: 0 | S27: 0 | T27: 0
B28: Total Logistics (₹) | C28: 2676.65 | D28: 1257.76 | E28: 12.29 | F28: 12.29 | G28: 12.29 | H28: 12.29 | I28: 12.29 | J28: 12.29 | K28: 602.21 | L28: 0 | M28: 0 | N28: 0 | O28: 0 | P28: 0 | Q28: 0 | R28: 0 | S28: 0 | T28: 0 | U28: 4610.36
B29: Ad Spend Allocated (₹) | C29: 14427.93 | D29: 1541.49 | E29: 8.26 | F29: 8.59 | G29: 9.36 | H29: 7.82 | I29: 9.14 | J29: 9.36 | K29: 383.06 | L29: 115.61 | M29: 31.27 | N29: 174.41 | O29: 71.35 | P29: 14.31 | Q29: 12.11 | R29: 80.93 | S29: 797.39 | T29: 18.5 | U29: 17720.89
B30: TCS (₹/net unit) [1% of NSP] | C30: 1.64 | D30: 2.5 | E30: 0.75 | F30: 0.78 | G30: 0.85 | H30: 0.71 | I30: 0.83 | J30: 0.85 | K30: 0.71 | L30: 0.7 | M30: 0.71 | N30: 0.88 | O30: 1.08 | P30: 1.3 | Q30: 1.1 | R30: 1.05 | S30: 1.02 | T30: 1.68 | U30: 1.56
B31: GST on MP Fees (₹/net unit) [18%] | C31: 1.62 | D31: 2.16 | E31: 1.26 | F31: 1.26 | G31: 1.26 | H31: 1.26 | I31: 1.26 | J31: 1.26 | K31: 1.44 | L31: 1.44 | M31: 1.26 | N31: 1.44 | O31: 1.62 | P31: 1.44 | Q31: 1.44 | R31: 1.62 | S31: 1.62 | T31: 1.62 | U31: 1.63
B32: Total Taxes (₹) | C32: 2604.74 | D32: 260.96 | E32: 2.01 | F32: 2.04 | G32: 2.11 | H32: 1.97 | I32: 2.09 | J32: 2.11 | K32: 105.35 | L32: 32.1 | M32: 7.88 | N32: 41.76 | O32: 16.2 | P32: 2.74 | Q32: 2.54 | R32: 18.69 | S32: 187.44 | T32: 3.3 | U32: 3296.03
B33: ⇒ Total Variable Costs excl. COGS (₹) | C33: 26900.32 | D33: 3732.21 | E33: 29.56 | F33: 29.92 | G33: 30.76 | H33: 29.08 | I33: 30.52 | J33: 30.76 | K33: 1482.62 | L33: 267.71 | M33: 67.15 | N33: 360.17 | O33: 141.55 | P33: 25.05 | Q33: 22.65 | R33: 162.62 | S33: 1623.83 | T33: 30.8 | U33: 34997.28
B34: ⇒ Total Cost incl. COGS (₹) | C34: 100687.97 | D34: 14075.41 | E34: 62.06 | F34: 59.32 | G34: 61.2 | H34: 60.28 | I34: 63.02 | J34: 77.68 | K34: 3932.13 | L34: 955.76 | M34: 242.39 | N34: 1213.73 | O34: 441.49 | P34: 119.05 | Q34: 107.63 | R34: 699.8 | S34: 6779.85 | T34: 117.8 | U34: 129756.57
A35: ⑥ OPERATING PROFIT / (LOSS)
A36: ⑥ Op P&L | B36: Operating Profit / (Loss) (₹) | C36: 30348.03 | D36: -75.41 | E36: 24.94 | F36: 18.68 | G36: 23.8 | H36: 10.72 | I36: 19.98 | J36: 7.32 | K36: -453.13 | L36: 94.24 | M36: 41.61 | N36: 370.27 | O36: 206.51 | P36: 10.95 | Q36: 2.37 | R36: 35.2 | S36: 462.15 | T36: 50.2 | U36: 31198.43
B37: Op Profit per Net Unit (₹) | C37: 37.98 | D37: -1.35 | E37: 24.94 | F37: 18.68 | G37: 23.8 | H37: 10.72 | I37: 19.98 | J37: 7.32 | K37: -9.25 | L37: 6.28 | M37: 10.4 | N37: 20.57 | O37: 34.42 | P37: 10.95 | Q37: 2.37 | R37: 5.03 | S37: 6.51 | T37: 50.2 | U37: 30.17
B38: Operating Margin (%) | C38: 0.232 | D38: -0.005 | E38: 0.287 | F38: 0.239 | G38: 0.28 | H38: 0.151 | I38: 0.241 | J38: 0.086 | K38: -0.13 | L38: 0.09 | M38: 0.147 | N38: 0.234 | O38: 0.319 | P38: 0.084 | Q38: 0.022 | R38: 0.048 | S38: 0.064 | T38: 0.299 | U38: 0.194
A39: ⑦ TDS — Deducted by Flipkart (Recoverable)
A40: ⑦ TDS | B40: TDS (₹) [0.1% on Net Revenue] | C40: 131.04 | D40: 14 | E40: 0.09 | F40: 0.08 | G40: 0.09 | H40: 0.07 | I40: 0.08 | J40: 0.09 | K40: 3.48 | L40: 1.05 | M40: 0.28 | N40: 1.58 | O40: 0.65 | P40: 0.13 | Q40: 0.11 | R40: 0.73 | S40: 7.24 | T40: 0.17 | U40: 160.96
A41: ⑧ NET PROFIT / (LOSS)
A42: ⑧ Net P&L | B42: Net Profit / (Loss) (₹) | C42: 30216.99 | D42: -89.41 | E42: 24.85 | F42: 18.6 | G42: 23.72 | H42: 10.65 | I42: 19.9 | J42: 7.24 | K42: -456.61 | L42: 93.19 | M42: 41.33 | N42: 368.69 | O42: 205.86 | P42: 10.82 | Q42: 2.26 | R42: 34.47 | S42: 454.91 | T42: 50.03 | U42: 31037.48
...

Sheet 📊 MTD Dashboard
A1: LIIMRA NATURALS | MTD & YTD PERFORMANCE DASHBOARD | FY 2026-27
A2: Current reporting month driven by ⚙ Config sheet cell 'Current Reporting Month'. All metrics auto-populate from 📅 Monthly PvA sheet. Enter actuals there to see live variances here.
A3: =" Reporting Month: "&CHOOSE('⚙ Config & Assumptions'!B41,"April","May","June","July","August","September","October","November","December","January","February","March")&" | FY 2026-27" -> Reporting Month: April | FY 2026-27 | H3: YTD Summary (Apr → Current Month)
A4: Metric | B4: Plan | C4: Actual | D4: Var ₹ | E4: Var % | F4: Status | H4: Metric | I4: Plan | J4: Actual | K4: Var ₹ | L4: Var % | M4: Status
A5: Net Units Sold | B5: ='📅 Monthly PvA'!AX10 -> 72 | C5: ='📅 Monthly PvA'!AY10 | D5: ='📅 Monthly PvA'!AZ10 | E5: ='📅 Monthly PvA'!BA10 | F5: =IF('📅 Monthly PvA'!BA10="","—",IF('📅 Monthly PvA'!BA10>='⚙ Config & Assumptions'!B42,"✔ On/Above",IF('📅 Monthly PvA'!BA10<='⚙ Config & Assumptions'!B43,"✘ Below","~ Near"))) -> — | H5: Net Units Sold | I5: ='📅 Monthly PvA'!BB10 -> 72 | J5: ='📅 Monthly PvA'!BC10 -> 0 | K5: ='📅 Monthly PvA'!BD10 | L5: ='📅 Monthly PvA'!BE10 | M5: =IF('📅 Monthly PvA'!BE10="","—",IF('📅 Monthly PvA'!BE10>='⚙ Config & Assumptions'!B42,"✔ On/Above",IF('📅 Monthly PvA'!BE10<='⚙ Config & Assumptions'!B43,"✘ Below","~ Near"))) -> —
A6: Net Revenue (₹) | B6: ='📅 Monthly PvA'!AX14 -> 11265 | C6: ='📅 Monthly PvA'!AY14 | D6: ='📅 Monthly PvA'!AZ14 | E6: ='📅 Monthly PvA'!BA14 | F6: =IF('📅 Monthly PvA'!BA14="","—",IF('📅 Monthly PvA'!BA14>='⚙ Config & Assumptions'!B42,"✔ On/Above",IF('📅 Monthly PvA'!BA14<='⚙ Config & Assumptions'!B43,"✘ Below","~ Near"))) -> — | H6: Net Revenue (₹) | I6: ='📅 Monthly PvA'!BB14 -> 11265 | J6: ='📅 Monthly PvA'!BC14 -> 0 | K6: ='📅 Monthly PvA'!BD14 | L6: ='📅 Monthly PvA'!BE14 | M6: =IF('📅 Monthly PvA'!BE14="","—",IF('📅 Monthly PvA'!BE14>='⚙ Config & Assumptions'!B42,"✔ On/Above",IF('📅 Monthly PvA'!BE14<='⚙ Config & Assumptions'!B43,"✘ Below","~ Near"))) -> —
A7: Total COGS (₹) | B7: ='📅 Monthly PvA'!AX16 -> 6633 | C7: ='📅 Monthly PvA'!AY16 | D7: ='📅 Monthly PvA'!AZ16 | E7: ='📅 Monthly PvA'!BA16 | F7: =IF('📅 Monthly PvA'!BA16="","—",IF('📅 Monthly PvA'!BA16>='⚙ Config & Assumptions'!B42,"✔ On/Above",IF('📅 Monthly PvA'!BA16<='⚙ Config & Assumptions'!B43,"✘ Below","~ Near"))) -> — | H7: Total COGS (₹) | I7: ='📅 Monthly PvA'!BB16 -> 6633 | J7: ='📅 Monthly PvA'!BC16 -> 0 | K7: ='📅 Monthly PvA'!BD16 | L7: ='📅 Monthly PvA'!BE16 | M7: =IF('📅 Monthly PvA'!BE16="","—",IF('📅 Monthly PvA'!BE16>='⚙ Config & Assumptions'!B42,"✔ On/Above",IF('📅 Monthly PvA'!BE16<='⚙ Config & Assumptions'!B43,"✘ Below","~ Near"))) -> —
A8: Gross Profit (₹) | B8: ='📅 Monthly PvA'!AX18 -> 4631 | C8: ='📅 Monthly PvA'!AY18 | D8: ='📅 Monthly PvA'!AZ18 | E8: ='📅 Monthly PvA'!BA18 | F8: =IF('📅 Monthly PvA'!BA18="","—",IF('📅 Monthly PvA'!BA18>='⚙ Config & Assumptions'!B42,"✔ On/Above",IF('📅 Monthly PvA'!BA18<='⚙ Config & Assumptions'!B43,"✘ Below","~ Near"))) -> — | H8: Gross Profit (₹) | I8: ='📅 Monthly PvA'!BB18 -> 4631 | J8: ='📅 Monthly PvA'!BC18 -> 0 | K8: ='📅 Monthly PvA'!BD18 | L8: ='📅 Monthly PvA'!BE18 | M8: =IF('📅 Monthly PvA'!BE18="","—",IF('📅 Monthly PvA'!BE18>='⚙ Config & Assumptions'!B42,"✔ On/Above",IF('📅 Monthly PvA'!BE18<='⚙ Config & Assumptions'!B43,"✘ Below","~ Near"))) -> —
A9: Gross Margin (%) | B9: ='📅 Monthly PvA'!AX19 -> 0.41109632 | C9: ='📅 Monthly PvA'!AY19 | D9: ='📅 Monthly PvA'!AZ19 | E9: ='📅 Monthly PvA'!BA19 | F9: =IF('📅 Monthly PvA'!BA19="","—",IF('📅 Monthly PvA'!BA19>='⚙ Config & Assumptions'!B42,"✔ On/Above",IF('📅 Monthly PvA'!BA19<='⚙ Config & Assumptions'!B43,"✘ Below","~ Near"))) -> — | H9: Gross Margin (%) | I9: ='📅 Monthly PvA'!BB19 -> 0.41109632 | J9: ='📅 Monthly PvA'!BC19 -> 0 | K9: ='📅 Monthly PvA'!BD19 | L9: ='📅 Monthly PvA'!BE19 | M9: =IF('📅 Monthly PvA'!BE19="","—",IF('📅 Monthly PvA'!BE19>='⚙ Config & Assumptions'!B42,"✔ On/Above",IF('📅 Monthly PvA'!BE19<='⚙ Config & Assumptions'!B43,"✘ Below","~ Near"))) -> —
A10: Ad Spend (₹) | B10: ='📅 Monthly PvA'!AX23 -> 1475 | C10: ='📅 Monthly PvA'!AY23 | D10: ='📅 Monthly PvA'!AZ23 | E10: ='📅 Monthly PvA'!BA23 | F10: =IF('📅 Monthly PvA'!BA23="","—",IF('📅 Monthly PvA'!BA23>='⚙ Config & Assumptions'!B42,"✔ On/Above",IF('📅 Monthly PvA'!BA23<='⚙ Config & Assumptions'!B43,"✘ Below","~ Near"))) -> — | H10: Ad Spend (₹) | I10: ='📅 Monthly PvA'!BB23 -> 1475 | J10: ='📅 Monthly PvA'!BC23 -> 0 | K10: ='📅 Monthly PvA'!BD23 | L10: ='📅 Monthly PvA'!BE23 | M10: =IF('📅 Monthly PvA'!BE23="","—",IF('📅 Monthly PvA'!BE23>='⚙ Config & Assumptions'!B42,"✔ On/Above",IF('📅 Monthly PvA'!BE23<='⚙ Config & Assumptions'!B43,"✘ Below","~ Near"))) -> —
A11: Operating Profit / (Loss) (₹) | B11: ='📅 Monthly PvA'!AX27 -> 1946 | C11: ='📅 Monthly PvA'!AY27 | D11: ='📅 Monthly PvA'!AZ27 | E11: ='📅 Monthly PvA'!BA27 | F11: =IF('📅 Monthly PvA'!BA27="","—",IF('📅 Monthly PvA'!BA27>='⚙ Config & Assumptions'!B42,"✔ On/Above",IF('📅 Monthly PvA'!BA27<='⚙ Config & Assumptions'!B43,"✘ Below","~ Near"))) -> — | H11: Operating Profit / (Loss) (₹) | I11: ='📅 Monthly PvA'!BB27 -> 1946 | J11: ='📅 Monthly PvA'!BC27 -> 0 | K11: ='📅 Monthly PvA'!BD27 | L11: ='📅 Monthly PvA'!BE27 | M11: =IF('📅 Monthly PvA'!BE27="","—",IF('📅 Monthly PvA'!BE27>='⚙ Config & Assumptions'!B42,"✔ On/Above",IF('📅 Monthly PvA'!BE27<='⚙ Config & Assumptions'!B43,"✘ Below","~ Near"))) -> —
A12: Operating Margin (%) | B12: ='📅 Monthly PvA'!AX28 -> 0.17274745 | C12: ='📅 Monthly PvA'!AY28 | D12: ='📅 Monthly PvA'!AZ28 | E12: ='📅 Monthly PvA'!BA28 | F12: =IF('📅 Monthly PvA'!BA28="","—",IF('📅 Monthly PvA'!BA28>='⚙ Config & Assumptions'!B42,"✔ On/Above",IF('📅 Monthly PvA'!BA28<='⚙ Config & Assumptions'!B43,"✘ Below","~ Near"))) -> — | H12: Operating Margin (%) | I12: ='📅 Monthly PvA'!BB28 -> 0.17274745 | J12: ='📅 Monthly PvA'!BC28 -> 0 | K12: ='📅 Monthly PvA'!BD28 | L12: ='📅 Monthly PvA'!BE28 | M12: =IF('📅 Monthly PvA'!BE28="","—",IF('📅 Monthly PvA'!BE28>='⚙ Config & Assumptions'!B42,"✔ On/Above",IF('📅 Monthly PvA'!BE28<='⚙ Config & Assumptions'!B43,"✘ Below","~ Near"))) -> —
A13: Net Profit / (Loss) (₹) | B13: ='📅 Monthly PvA'!AX32 -> 1935 | C13: ='📅 Monthly PvA'!AY32 | D13: ='📅 Monthly PvA'!AZ32 | E13: ='📅 Monthly PvA'!BA32 | F13: =IF('📅 Monthly PvA'!BA32="","—",IF('📅 Monthly PvA'!BA32>='⚙ Config & Assumptions'!B42,"✔ On/Above",IF('📅 Monthly PvA'!BA32<='⚙ Config & Assumptions'!B43,"✘ Below","~ Near"))) -> — | H13: Net Profit / (Loss) (₹) | I13: ='📅 Monthly PvA'!BB32 -> 1935 | J13: ='📅 Monthly PvA'!BC32 -> 0 | K13: ='📅 Monthly PvA'!BD32 | L13: ='📅 Monthly PvA'!BE32 | M13: =IF('📅 Monthly PvA'!BE32="","—",IF('📅 Monthly PvA'!BE32>='⚙ Config & Assumptions'!B42,"✔ On/Above",IF('📅 Monthly PvA'!BE32<='⚙ Config & Assumptions'!B43,"✘ Below","~ Near"))) -> —
A14: Net Margin (%) | B14: ='📅 Monthly PvA'!AX33 -> 0.17177097 | C14: ='📅 Monthly PvA'!AY33 | D14: ='📅 Monthly PvA'!AZ33 | E14: ='📅 Monthly PvA'!BA33 | F14: =IF('📅 Monthly PvA'!BA33="","—",IF('📅 Monthly PvA'!BA33>='⚙ Config & Assumptions'!B42,"✔ On/Above",IF('📅 Monthly PvA'!BA33<='⚙ Config & Assumptions'!B43,"✘ Below","~ Near"))) -> — | H14: Net Margin (%) | I14: ='📅 Monthly PvA'!BB33 -> 0.17177097 | J14: ='📅 Monthly PvA'!BC33 -> 0 | K14: ='📅 Monthly PvA'!BD33 | L14: ='📅 Monthly PvA'!BE33 | M14: =IF('📅 Monthly PvA'!BE33="","—",IF('📅 Monthly PvA'!BE33>='⚙ Config & Assumptions'!B42,"✔ On/Above",IF('📅 Monthly PvA'!BE33<='⚙ Config & Assumptions'!B43,"✘ Below","~ Near"))) -> —
A15: Fixed Overheads (₹) | B15: ='📅 Monthly PvA'!AX35 -> 0 | C15: ='📅 Monthly PvA'!AY35 | D15: ='📅 Monthly PvA'!AZ35 | E15: ='📅 Monthly PvA'!BA35 | F15: =IF('📅 Monthly PvA'!BA35="","—",IF('📅 Monthly PvA'!BA35>='⚙ Config & Assumptions'!B42,"✔ On/Above",IF('📅 Monthly PvA'!BA35<='⚙ Config & Assumptions'!B43,"✘ Below","~ Near"))) -> — | H15: Fixed Overheads (₹) | I15: ='📅 Monthly PvA'!BB35 -> 0 | J15: ='📅 Monthly PvA'!BC35 -> 0 | K15: ='📅 Monthly PvA'!BD35 | L15: ='📅 Monthly PvA'!BE35 | M15: =IF('📅 Monthly PvA'!BE35="","—",IF('📅 Monthly PvA'!BE35>='⚙ Config & Assumptions'!B42,"✔ On/Above",IF('📅 Monthly PvA'!BE35<='⚙ Config & Assumptions'!B43,"✘ Below","~ Near"))) -> —
A16: Net Profit after Fixed OH (₹) | B16: ='📅 Monthly PvA'!AX36 -> 1935 | C16: ='📅 Monthly PvA'!AY36 | D16: ='📅 Monthly PvA'!AZ36 | E16: ='📅 Monthly PvA'!BA36 | F16: =IF('📅 Monthly PvA'!BA36="","—",IF('📅 Monthly PvA'!BA36>='⚙ Config & Assumptions'!B42,"✔ On/Above",IF('📅 Monthly PvA'!BA36<='⚙ Config & Assumptions'!B43,"✘ Below","~ Near"))) -> — | H16: Net Profit after Fixed OH (₹) | I16: ='📅 Monthly PvA'!BB36 -> 1935 | J16: ='📅 Monthly PvA'!BC36 -> 0 | K16: ='📅 Monthly PvA'!BD36 | L16: ='📅 Monthly PvA'!BE36 | M16: =IF('📅 Monthly PvA'!BE36="","—",IF('📅 Monthly PvA'!BE36>='⚙ Config & Assumptions'!B42,"✔ On/Above",IF('📅 Monthly PvA'!BE36<='⚙ Config & Assumptions'!B43,"✘ Below","~ Near"))) -> —
A17: Contribution per Unit (₹) | B17: ='📅 Monthly PvA'!AX39 -> 47.2828 | C17: ='📅 Monthly PvA'!AY39 | D17: ='📅 Monthly PvA'!AZ39 | E17: ='📅 Monthly PvA'!BA39 | F17: =IF('📅 Monthly PvA'!BA39="","—",IF('📅 Monthly PvA'!BA39>='⚙ Config & Assumptions'!B42,"✔ On/Above",IF('📅 Monthly PvA'!BA39<='⚙ Config & Assumptions'!B43,"✘ Below","~ Near"))) -> — | H17: Contribution per Unit (₹) | I17: ='📅 Monthly PvA'!BB39 -> 47.2828 | J17: ='📅 Monthly PvA'!BC39 -> 0 | K17: ='📅 Monthly PvA'!BD39 | L17: ='📅 Monthly PvA'!BE39 | M17: =IF('📅 Monthly PvA'!BE39="","—",IF('📅 Monthly PvA'!BE39>='⚙ Config & Assumptions'!B42,"✔ On/Above",IF('📅 Monthly PvA'!BE39<='⚙ Config & Assumptions'!B43,"✘ Below","~ Near"))) -> —
A18: Bank Settlement (₹) — Estimated | B18: ='📅 Monthly PvA'!AX42 -> 10367 | C18: ='📅 Monthly PvA'!AY42 | D18: ='📅 Monthly PvA'!AZ42 | E18: ='📅 Monthly PvA'!BA42 | F18: =IF('📅 Monthly PvA'!BA42="","—",IF('📅 Monthly PvA'!BA42>='⚙ Config & Assumptions'!B42,"✔ On/Above",IF('📅 Monthly PvA'!BA42<='⚙ Config & Assumptions'!B43,"✘ Below","~ Near"))) -> — | H18: Bank Settlement (₹) — Estimated | I18: ='📅 Monthly PvA'!BB42 -> 10367 | J18: ='📅 Monthly PvA'!BC42 -> 0 | K18: ='📅 Monthly PvA'!BD42 | L18: ='📅 Monthly PvA'!BE42 | M18: =IF('📅 Monthly PvA'!BE42="","—",IF('📅 Monthly PvA'!BE42>='⚙ Config & Assumptions'!B42,"✔ On/Above",IF('📅 Monthly PvA'!BE42<='⚙ Config & Assumptions'!B43,"✘ Below","~ Near"))) -> —

Sheet 📅 Monthly PvA
A1: LIIMRA NATURALS | MONTHLY PLAN vs ACTUAL | FY 2026-27 (Apr 2026 – Mar 2027)
A2: Plan = seasonality-weighted annual targets from ⚙ Config sheet · Actual = enter monthly data in GREEN cells · Variance = Actual − Plan · MTD & YTD driven by current reporting month in Config
A3: Metric | B3: April | F3: May | J3: June | N3: July | R3: August | V3: September | Z3: October | AD3: November | AH3: December | AL3: January | AP3: February | AT3: March | AX3: ◆ MTD | BB3: ◆ YTD
A4: Section / Metric | B4: Plan | C4: Actual | D4: Var ₹ | E4: Var % | F4: Plan | G4: Actual | H4: Var ₹ | I4: Var % | J4: Plan | K4: Actual | L4: Var ₹ | M4: Var % | N4: Plan | O4: Actual | P4: Var ₹ | Q4: Var % | R4: Plan | S4: Actual | T4: Var ₹ | U4: Var % | V4: Plan | W4: Actual | X4: Var ₹ | Y4: Var % | Z4: Plan | AA4: Actual | AB4: Var ₹ | AC4: Var % | AD4: Plan | AE4: Actual | AF4: Var ₹ | AG4: Var % | AH4: Plan | AI4: Actual | AJ4: Var ₹ | AK4: Var % | AL4: Plan | AM4: Actual | AN4: Var ₹ | AO4: Var % | AP4: Plan | AQ4: Actual | AR4: Var ₹ | AS4: Var % | AT4: Plan | AU4: Actual | AV4: Var ₹ | AW4: Var % | AX4: Plan | AY4: Actual | AZ4: Var ₹ | BA4: Var % | BB4: Plan | BC4: Actual | BD4: Var ₹ | BE4: Var %
A6: ① VOLUME
A7: Gross Units (Plan) | B7: =ROUND('⚙ Config & Assumptions'!B5*'⚙ Config & Assumptions'!B7,0) -> 79 | D7: =IF(C7="","",C7-B7) | E7: =IF(OR(C7="",B7=0),"",(C7-B7)/B7) | F7: =ROUND('⚙ Config & Assumptions'!B5*'⚙ Config & Assumptions'!B8,0) -> 84 | H7: =IF(G7="","",G7-F7) | I7: =IF(OR(G7="",F7=0),"",(G7-F7)/F7) | J7: =ROUND('⚙ Config & Assumptions'!B5*'⚙ Config & Assumptions'!B9,0) -> 73 | L7: =IF(K7="","",K7-J7) | M7: =IF(OR(K7="",J7=0),"",(K7-J7)/J7) | N7: =ROUND('⚙ Config & Assumptions'!B5*'⚙ Config & Assumptions'!B10,0) -> 84 | P7: =IF(O7="","",O7-N7) | Q7: =IF(OR(O7="",N7=0),"",(O7-N7)/N7) | R7: =ROUND('⚙ Config & Assumptions'!B5*'⚙ Config & Assumptions'!B11,0) -> 101 | T7: =IF(S7="","",S7-R7) | U7: =IF(OR(S7="",R7=0),"",(S7-R7)/R7) | V7: =ROUND('⚙ Config & Assumptions'!B5*'⚙ Config & Assumptions'!B12,0) -> 107 | X7: =IF(W7="","",W7-V7) | Y7: =IF(OR(W7="",V7=0),"",(W7-V7)/V7) | Z7: =ROUND('⚙ Config & Assumptions'!B5*'⚙ Config & Assumptions'!B13,0) -> 112 | AB7: =IF(AA7="","",AA7-Z7) | AC7: =IF(OR(AA7="",Z7=0),"",(AA7-Z7)/Z7) | AD7: =ROUND('⚙ Config & Assumptions'!B5*'⚙ Config & Assumptions'!B14,0) -> 107 | AF7: =IF(AE7="","",AE7-AD7) | AG7: =IF(OR(AE7="",AD7=0),"",(AE7-AD7)/AD7) | AH7: =ROUND('⚙ Config & Assumptions'!B5*'⚙ Config & Assumptions'!B15,0) -> 101 | AJ7: =IF(AI7="","",AI7-AH7) | AK7: =IF(OR(AI7="",AH7=0),"",(AI7-AH7)/AH7) | AL7: =ROUND('⚙ Config & Assumptions'!B5*'⚙ Config & Assumptions'!B16,0) -> 101 | AN7: =IF(AM7="","",AM7-AL7) | AO7: =IF(OR(AM7="",AL7=0),"",(AM7-AL7)/AL7) | AP7: =ROUND('⚙ Config & Assumptions'!B5*'⚙ Config & Assumptions'!B17,0) -> 95 | AR7: =IF(AQ7="","",AQ7-AP7) | AS7: =IF(OR(AQ7="",AP7=0),"",(AQ7-AP7)/AP7) | AT7: =ROUND('⚙ Config & Assumptions'!B5*'⚙ Config & Assumptions'!B18,0) -> 79 | AV7: =IF(AU7="","",AU7-AT7) | AW7: =IF(OR(AU7="",AT7=0),"",(AU7-AT7)/AT7) | AX7: =CHOOSE('⚙ Config & Assumptions'!B41,B7,F7,J7,N7,R7,V7,Z7,AD7,AH7,AL7,AP7,AT7) -> 79 | AY7: =IF(CHOOSE('⚙ Config & Assumptions'!B41,C7,G7,K7,O7,S7,W7,AA7,AE7,AI7,AM7,AQ7,AU7)="","",CHOOSE('⚙ Config & Assumptions'!B41,C7,G7,K7,O7,S7,W7,AA7,AE7,AI7,AM7,AQ7,AU7)) | AZ7: =IF(AY7="","",AY7-AX7) | BA7: =IF(OR(AY7="",AX7=0),"",(AY7-AX7)/AX7) | BB7: =IF('⚙ Config & Assumptions'!B41>=1,B7,0)+IF('⚙ Config & Assumptions'!B41>=2,F7,0)+IF('⚙ Config & Assumptions'!B41>=3,J7,0)+IF('⚙ Config & Assumptions'!B41>=4,N7,0)+IF('⚙ Config & Assumptions'!B41>=5,R7,0)+IF('⚙ Config & Assumptions'!B41>=6,V7,0)+IF('⚙ Config & Assumptions'!B41>=7,Z7,0)+IF('⚙ Config & Assumptions'!B41>=8,AD7,0)+IF('⚙ Config & Assumptions'!B41>=9,AH7,0)+IF('⚙ Config & Assumptions'!B41>=10,AL7,0)+IF('⚙ Config & Assumptions'!B41>=11,AP7,0)+IF('⚙ Config & Assumptions'!B41>=12,AT7,0) -> 79 | BC7: =IF(AND('⚙ Config & Assumptions'!B41>=1,C7<>""),C7,0)+IF(AND('⚙ Config & Assumptions'!B41>=2,G7<>""),G7,0)+IF(AND('⚙ Config & Assumptions'!B41>=3,K7<>""),K7,0)+IF(AND('⚙ Config & Assumptions'!B41>=4,O7<>""),O7,0)+IF(AND('⚙ Config & Assumptions'!B41>=5,S7<>""),S7,0)+IF(AND('⚙ Config & Assumptions'!B41>=6,W7<>""),W7,0)+IF(AND('⚙ Config & Assumptions'!B41>=7,AA7<>""),AA7,0)+IF(AND('⚙ Config & Assumptions'!B41>=8,AE7<>""),AE7,0)+IF(AND('⚙ Config & Assumptions'!B41>=9,AI7<>""),AI7,0)+IF(AND('⚙ Config & Assumptions'!B41>=10,AM7<>""),AM7,0)+IF(AND('⚙ Config & Assumptions'!B41>=11,AQ7<>""),AQ7,0)+IF(AND('⚙ Config & Assumptions'!B41>=12,AU7<>""),AU7,0) -> 0 | BD7: =IF(BC7=0,"",BC7-BB7) | BE7: =IF(OR(BC7=0,BB7=0),"",(BC7-BB7)/BB7)
A8: Return Rate (%) | B8: ='⚙ Config & Assumptions'!B22 -> 0.0793 | D8: =IF(C8="","",C8-B8) | E8: =IF(OR(C8="",B8=0),"",(C8-B8)/B8) | F8: ='⚙ Config & Assumptions'!B22 -> 0.0793 | H8: =IF(G8="","",G8-F8) | I8: =IF(OR(G8="",F8=0),"",(G8-F8)/F8) | J8: ='⚙ Config & Assumptions'!B22 -> 0.0793 | L8: =IF(K8="","",K8-J8) | M8: =IF(OR(K8="",J8=0),"",(K8-J8)/J8) | N8: ='⚙ Config & Assumptions'!B22 -> 0.0793 | P8: =IF(O8="","",O8-N8) | Q8: =IF(OR(O8="",N8=0),"",(O8-N8)/N8) | R8: ='⚙ Config & Assumptions'!B22 -> 0.0793 | T8: =IF(S8="","",S8-R8) | U8: =IF(OR(S8="",R8=0),"",(S8-R8)/R8) | V8: ='⚙ Config & Assumptions'!B22 -> 0.0793 | X8: =IF(W8="","",W8-V8) | Y8: =IF(OR(W8="",V8=0),"",(W8-V8)/V8) | Z8: ='⚙ Config & Assumptions'!B22 -> 0.0793 | AB8: =IF(AA8="","",AA8-Z8) | AC8: =IF(OR(AA8="",Z8=0),"",(AA8-Z8)/Z8) | AD8: ='⚙ Config & Assumptions'!B22 -> 0.0793 | AF8: =IF(AE8="","",AE8-AD8) | AG8: =IF(OR(AE8="",AD8=0),"",(AE8-AD8)/AD8) | AH8: ='⚙ Config & Assumptions'!B22 -> 0.0793 | AJ8: =IF(AI8="","",AI8-AH8) | AK8: =IF(OR(AI8="",AH8=0),"",(AI8-AH8)/AH8) | AL8: ='⚙ Config & Assumptions'!B22 -> 0.0793 | AN8: =IF(AM8="","",AM8-AL8) | AO8: =IF(OR(AM8="",AL8=0),"",(AM8-AL8)/AL8) | AP8: ='⚙ Config & Assumptions'!B22 -> 0.0793 | AR8: =IF(AQ8="","",AQ8-AP8) | AS8: =IF(OR(AQ8="",AP8=0),"",(AQ8-AP8)/AP8) | AT8: ='⚙ Config & Assumptions'!B22 -> 0.0793 | AV8: =IF(AU8="","",AU8-AT8) | AW8: =IF(OR(AU8="",AT8=0),"",(AU8-AT8)/AT8) | AX8: =CHOOSE('⚙ Config & Assumptions'!B41,B8,F8,J8,N8,R8,V8,Z8,AD8,AH8,AL8,AP8,AT8) -> 0.0793 | AY8: =IF(CHOOSE('⚙ Config & Assumptions'!B41,C8,G8,K8,O8,S8,W8,AA8,AE8,AI8,AM8,AQ8,AU8)="","",CHOOSE('⚙ Config & Assumptions'!B41,C8,G8,K8,O8,S8,W8,AA8,AE8,AI8,AM8,AQ8,AU8)) | AZ8: =IF(AY8="","",AY8-AX8) | BA8: =IF(OR(AY8="",AX8=0),"",(AY8-AX8)/AX8) | BB8: =IF('⚙ Config & Assumptions'!B41>=1,B8,0)+IF('⚙ Config & Assumptions'!B41>=2,F8,0)+IF('⚙ Config & Assumptions'!B41>=3,J8,0)+IF('⚙ Config & Assumptions'!B41>=4,N8,0)+IF('⚙ Config & Assumptions'!B41>=5,R8,0)+IF('⚙ Config & Assumptions'!B41>=6,V8,0)+IF('⚙ Config & Assumptions'!B41>=7,Z8,0)+IF('⚙ Config & Assumptions'!B41>=8,AD8,0)+IF('⚙ Config & Assumptions'!B41>=9,AH8,0)+IF('⚙ Config & Assumptions'!B41>=10,AL8,0)+IF('⚙ Config & Assumptions'!B41>=11,AP8,0)+IF('⚙ Config & Assumptions'!B41>=12,AT8,0) -> 0.0793 | BC8: =IF(AND('⚙ Config & Assumptions'!B41>=1,C8<>""),C8,0)+IF(AND('⚙ Config & Assumptions'!B41>=2,G8<>""),G8,0)+IF(AND('⚙ Config & Assumptions'!B41>=3,K8<>""),K8,0)+IF(AND('⚙ Config & Assumptions'!B41>=4,O8<>""),O8,0)+IF(AND('⚙ Config & Assumptions'!B41>=5,S8<>""),S8,0)+IF(AND('⚙ Config & Assumptions'!B41>=6,W8<>""),W8,0)+IF(AND('⚙ Config & Assumptions'!B41>=7,AA8<>""),AA8,0)+IF(AND('⚙ Config & Assumptions'!B41>=8,AE8<>""),AE8,0)+IF(AND('⚙ Config & Assumptions'!B41>=9,AI8<>""),AI8,0)+IF(AND('⚙ Config & Assumptions'!B41>=10,AM8<>""),AM8,0)+IF(AND('⚙ Config & Assumptions'!B41>=11,AQ8<>""),AQ8,0)+IF(AND('⚙ Config & Assumptions'!B41>=12,AU8<>""),AU8,0) -> 0 | BD8: =IF(BC8=0,"",BC8-BB8) | BE8: =IF(OR(BC8=0,BB8=0),"",(BC8-BB8)/BB8)
A9: Returns (Units) | B9: =ROUND('⚙ Config & Assumptions'!B5*'⚙ Config & Assumptions'!B7*'⚙ Config & Assumptions'!B22,0) -> 6 | D9: =IF(C9="","",C9-B9) | E9: =IF(OR(C9="",B9=0),"",(C9-B9)/B9) | F9: =ROUND('⚙ Config & Assumptions'!B5*'⚙ Config & Assumptions'!B8*'⚙ Config & Assumptions'!B22,0) -> 7 | H9: =IF(G9="","",G9-F9) | I9: =IF(OR(G9="",F9=0),"",(G9-F9)/F9) | J9: =ROUND('⚙ Config & Assumptions'!B5*'⚙ Config & Assumptions'!B9*'⚙ Config & Assumptions'!B22,0) -> 6 | L9: =IF(K9="","",K9-J9) | M9: =IF(OR(K9="",J9=0),"",(K9-J9)/J9) | N9: =ROUND('⚙ Config & Assumptions'!B5*'⚙ Config & Assumptions'!B10*'⚙ Config & Assumptions'!B22,0) -> 7 | P9: =IF(O9="","",O9-N9) | Q9: =IF(OR(O9="",N9=0),"",(O9-N9)/N9) | R9: =ROUND('⚙ Config & Assumptions'!B5*'⚙ Config & Assumptions'!B11*'⚙ Config & Assumptions'!B22,0) -> 8 | T9: =IF(S9="","",S9-R9) | U9: =IF(OR(S9="",R9=0),"",(S9-R9)/R9) | V9: =ROUND('⚙ Config & Assumptions'!B5*'⚙ Config & Assumptions'!B12*'⚙ Config & Assumptions'!B22,0) -> 8 | X9: =IF(W9="","",W9-V9) | Y9: =IF(OR(W9="",V9=0),"",(W9-V9)/V9) | Z9: =ROUND('⚙ Config & Assumptions'!B5*'⚙ Config & Assumptions'!B13*'⚙ Config & Assumptions'!B22,0) -> 9 | AB9: =IF(AA9="","",AA9-Z9) | AC9: =IF(OR(AA9="",Z9=0),"",(AA9-Z9)/Z9) | AD9: =ROUND('⚙ Config & Assumptions'!B5*'⚙ Config & Assumptions'!B14*'⚙ Config & Assumptions'!B22,0) -> 8 | AF9: =IF(AE9="","",AE9-AD9) | AG9: =IF(OR(AE9="",AD9=0),"",(AE9-AD9)/AD9) | AH9: =ROUND('⚙ Config & Assumptions'!B5*'⚙ Config & Assumptions'!B15*'⚙ Config & Assumptions'!B22,0) -> 8 | AJ9: =IF(AI9="","",AI9-AH9) | AK9: =IF(OR(AI9="",AH9=0),"",(AI9-AH9)/AH9) | AL9: =ROUND('⚙ Config & Assumptions'!B5*'⚙ Config & Assumptions'!B16*'⚙ Config & Assumptions'!B22,0) -> 8 | AN9: =IF(AM9="","",AM9-AL9) | AO9: =IF(OR(AM9="",AL9=0),"",(AM9-AL9)/AL9) | AP9: =ROUND('⚙ Config & Assumptions'!B5*'⚙ Config & Assumptions'!B17*'⚙ Config & Assumptions'!B22,0) -> 8 | AR9: =IF(AQ9="","",AQ9-AP9) | AS9: =IF(OR(AQ9="",AP9=0),"",(AQ9-AP9)/AP9) | AT9: =ROUND('⚙ Config & Assumptions'!B5*'⚙ Config & Assumptions'!B18*'⚙ Config & Assumptions'!B22,0) -> 6 | AV9: =IF(AU9="","",AU9-AT9) | AW9: =IF(OR(AU9="",AT9=0),"",(AU9-AT9)/AT9) | AX9: =CHOOSE('⚙ Config & Assumptions'!B41,B9,F9,J9,N9,R9,V9,Z9,AD9,AH9,AL9,AP9,AT9) -> 6 | AY9: =IF(CHOOSE('⚙ Config & Assumptions'!B41,C9,G9,K9,O9,S9,W9,AA9,AE9,AI9,AM9,AQ9,AU9)="","",CHOOSE('⚙ Config & Assumptions'!B41,C9,G9,K9,O9,S9,W9,AA9,AE9,AI9,AM9,AQ9,AU9)) | AZ9: =IF(AY9="","",AY9-AX9) | BA9: =IF(OR(AY9="",AX9=0),"",(AY9-AX9)/AX9) | BB9: =IF('⚙ Config & Assumptions'!B41>=1,B9,0)+IF('⚙ Config & Assumptions'!B41>=2,F9,0)+IF('⚙ Config & Assumptions'!B41>=3,J9,0)+IF('⚙ Config & Assumptions'!B41>=4,N9,0)+IF('⚙ Config & Assumptions'!B41>=5,R9,0)+IF('⚙ Config & Assumptions'!B41>=6,V9,0)+IF('⚙ Config & Assumptions'!B41>=7,Z9,0)+IF('⚙ Config & Assumptions'!B41>=8,AD9,0)+IF('⚙ Config & Assumptions'!B41>=9,AH9,0)+IF('⚙ Config & Assumptions'!B41>=10,AL9,0)+IF('⚙ Config & Assumptions'!B41>=11,AP9,0)+IF('⚙ Config & Assumptions'!B41>=12,AT9,0) -> 6 | BC9: =IF(AND('⚙ Config & Assumptions'!B41>=1,C9<>""),C9,0)+IF(AND('⚙ Config & Assumptions'!B41>=2,G9<>""),G9,0)+IF(AND('⚙ Config & Assumptions'!B41>=3,K9<>""),K9,0)+IF(AND('⚙ Config & Assumptions'!B41>=4,O9<>""),O9,0)+IF(AND('⚙ Config & Assumptions'!B41>=5,S9<>""),S9,0)+IF(AND('⚙ Config & Assumptions'!B41>=6,W9<>""),W9,0)+IF(AND('⚙ Config & Assumptions'!B41>=7,AA9<>""),AA9,0)+IF(AND('⚙ Config & Assumptions'!B41>=8,AE9<>""),AE9,0)+IF(AND('⚙ Config & Assumptions'!B41>=9,AI9<>""),AI9,0)+IF(AND('⚙ Config & Assumptions'!B41>=10,AM9<>""),AM9,0)+IF(AND('⚙ Config & Assumptions'!B41>=11,AQ9<>""),AQ9,0)+IF(AND('⚙ Config & Assumptions'!B41>=12,AU9<>""),AU9,0) -> 0 | BD9: =IF(BC9=0,"",BC9-BB9) | BE9: =IF(OR(BC9=0,BB9=0),"",(BC9-BB9)/BB9)
A10: ⇒ Net Units Sold | B10: =ROUND('⚙ Config & Assumptions'!B5*'⚙ Config & Assumptions'!B7*(1-'⚙ Config & Assumptions'!B22),0) -> 72 | D10: =IF(C10="","",C10-B10) | E10: =IF(OR(C10="",B10=0),"",(C10-B10)/B10) | F10: =ROUND('⚙ Config & Assumptions'!B5*'⚙ Config & Assumptions'!B8*(1-'⚙ Config & Assumptions'!B22),0) -> 78 | H10: =IF(G10="","",G10-F10) | I10: =IF(OR(G10="",F10=0),"",(G10-F10)/F10) | J10: =ROUND('⚙ Config & Assumptions'!B5*'⚙ Config & Assumptions'!B9*(1-'⚙ Config & Assumptions'!B22),0) -> 67 | L10: =IF(K10="","",K10-J10) | M10: =IF(OR(K10="",J10=0),"",(K10-J10)/J10) | N10: =ROUND('⚙ Config & Assumptions'!B5*'⚙ Config & Assumptions'!B10*(1-'⚙ Config & Assumptions'!B22),0) -> 78 | P10: =IF(O10="","",O10-N10) | Q10: =IF(OR(O10="",N10=0),"",(O10-N10)/N10) | R10: =ROUND('⚙ Config & Assumptions'!B5*'⚙ Config & Assumptions'!B11*(1-'⚙ Config & Assumptions'!B22),0) -> 93 | T10: =IF(S10="","",S10-R10) | U10: =IF(OR(S10="",R10=0),"",(S10-R10)/R10) | V10: =ROUND('⚙ Config & Assumptions'!B5*'⚙ Config & Assumptions'!B12*(1-'⚙ Config & Assumptions'!B22),0) -> 98 | X10: =IF(W10="","",W10-V10) | Y10: =IF(OR(W10="",V10=0),"",(W10-V10)/V10) | Z10: =ROUND('⚙ Config & Assumptions'!B5*'⚙ Config & Assumptions'!B13*(1-'⚙ Config & Assumptions'!B22),0) -> 103 | AB10: =IF(AA10="","",AA10-Z10) | AC10: =IF(OR(AA10="",Z10=0),"",(AA10-Z10)/Z10) | AD10: =ROUND('⚙ Config & Assumptions'!B5*'⚙ Config & Assumptions'!B14*(1-'⚙ Config & Assumptions'!B22),0) -> 98 | AF10: =IF(AE10="","",AE10-AD10) | AG10: =IF(OR(AE10="",AD10=0),"",(AE10-AD10)/AD10) | AH10: =ROUND('⚙ Config & Assumptions'!B5*'⚙ Config & Assumptions'!B15*(1-'⚙ Config & Assumptions'!B22),0) -> 93 | AJ10: =IF(AI10="","",AI10-AH10) | AK10: =IF(OR(AI10="",AH10=0),"",(AI10-AH10)/AH10) | AL10: =ROUND('⚙ Config & Assumptions'!B5*'⚙ Config & Assumptions'!B16*(1-'⚙ Config & Assumptions'!B22),0) -> 93 | AN10: =IF(AM10="","",AM10-AL10) | AO10: =IF(OR(AM10="",AL10=0),"",(AM10-AL10)/AL10) | AP10: =ROUND('⚙ Config & Assumptions'!B5*'⚙ Config & Assumptions'!B17*(1-'⚙ Config & Assumptions'!B22),0) -> 88 | AR10: =IF(AQ10="","",AQ10-AP10) | AS10: =IF(OR(AQ10="",AP10=0),"",(AQ10-AP10)/AP10) | AT10: =ROUND('⚙ Config & Assumptions'!B5*'⚙ Config & Assumptions'!B18*(1-'⚙ Config & Assumptions'!B22),0) -> 72 | AV10: =IF(AU10="","",AU10-AT10) | AW10: =IF(OR(AU10="",AT10=0),"",(AU10-AT10)/AT10) | AX10: =CHOOSE('⚙ Config & Assumptions'!B41,B10,F10,J10,N10,R10,V10,Z10,AD10,AH10,AL10,AP10,AT10) -> 72 | AY10: =IF(CHOOSE('⚙ Config & Assumptions'!B41,C10,G10,K10,O10,S10,W10,AA10,AE10,AI10,AM10,AQ10,AU10)="","",CHOOSE('⚙ Config & Assumptions'!B41,C10,G10,K10,O10,S10,W10,AA10,AE10,AI10,AM10,AQ10,AU10)) | AZ10: =IF(AY10="","",AY10-AX10) | BA10: =IF(OR(AY10="",AX10=0),"",(AY10-AX10)/AX10) | BB10: =IF('⚙ Config & Assumptions'!B41>=1,B10,0)+IF('⚙ Config & Assumptions'!B41>=2,F10,0)+IF('⚙ Config & Assumptions'!B41>=3,J10,0)+IF('⚙ Config & Assumptions'!B41>=4,N10,0)+IF('⚙ Config & Assumptions'!B41>=5,R10,0)+IF('⚙ Config & Assumptions'!B41>=6,V10,0)+IF('⚙ Config & Assumptions'!B41>=7,Z10,0)+IF('⚙ Config & Assumptions'!B41>=8,AD10,0)+IF('⚙ Config & Assumptions'!B41>=9,AH10,0)+IF('⚙ Config & Assumptions'!B41>=10,AL10,0)+IF('⚙ Config & Assumptions'!B41>=11,AP10,0)+IF('⚙ Config & Assumptions'!B41>=12,AT10,0) -> 72 | BC10: =IF(AND('⚙ Config & Assumptions'!B41>=1,C10<>""),C10,0)+IF(AND('⚙ Config & Assumptions'!B41>=2,G10<>""),G10,0)+IF(AND('⚙ Config & Assumptions'!B41>=3,K10<>""),K10,0)+IF(AND('⚙ Config & Assumptions'!B41>=4,O10<>""),O10,0)+IF(AND('⚙ Config & Assumptions'!B41>=5,S10<>""),S10,0)+IF(AND('⚙ Config & Assumptions'!B41>=6,W10<>""),W10,0)+IF(AND('⚙ Config & Assumptions'!B41>=7,AA10<>""),AA10,0)+IF(AND('⚙ Config & Assumptions'!B41>=8,AE10<>""),AE10,0)+IF(AND('⚙ Config & Assumptions'!B41>=9,AI10<>""),AI10,0)+IF(AND('⚙ Config & Assumptions'!B41>=10,AM10<>""),AM10,0)+IF(AND('⚙ Config & Assumptions'!B41>=11,AQ10<>""),AQ10,0)+IF(AND('⚙ Config & Assumptions'!B41>=12,AU10<>""),AU10,0) -> 0 | BD10: =IF(BC10=0,"",BC10-BB10) | BE10: =IF(OR(BC10=0,BB10=0),"",(BC10-BB10)/BB10)
A11: ② REVENUE
A12: Gross Revenue (₹) | B12: =ROUND('⚙ Config & Assumptions'!B5*'⚙ Config & Assumptions'!B7*'⚙ Config & Assumptions'!B21,0) -> 12235 | D12: =IF(C12="","",C12-B12) | E12: =IF(OR(C12="",B12=0),"",(C12-B12)/B12) | F12: =ROUND('⚙ Config & Assumptions'!B5*'⚙ Config & Assumptions'!B8*'⚙ Config & Assumptions'!B21,0) -> 13109 | H12: =IF(G12="","",G12-F12) | I12: =IF(OR(G12="",F12=0),"",(G12-F12)/F12) | J12: =ROUND('⚙ Config & Assumptions'!B5*'⚙ Config & Assumptions'!B9*'⚙ Config & Assumptions'!B21,0) -> 11361 | L12: =IF(K12="","",K12-J12) | M12: =IF(OR(K12="",J12=0),"",(K12-J12)/J12) | N12: =ROUND('⚙ Config & Assumptions'!B5*'⚙ Config & Assumptions'!B10*'⚙ Config & Assumptions'!B21,0) -> 13109 | P12: =IF(O12="","",O12-N12) | Q12: =IF(OR(O12="",N12=0),"",(O12-N12)/N12) | R12: =ROUND('⚙ Config & Assumptions'!B5*'⚙ Config & Assumptions'!B11*'⚙ Config & Assumptions'!B21,0) -> 15731 | T12: =IF(S12="","",S12-R12) | U12: =IF(OR(S12="",R12=0),"",(S12-R12)/R12) | V12: =ROUND('⚙ Config & Assumptions'!B5*'⚙ Config & Assumptions'!B12*'⚙ Config & Assumptions'!B21,0) -> 16604 | X12: =IF(W12="","",W12-V12) | Y12: =IF(OR(W12="",V12=0),"",(W12-V12)/V12) | Z12: =ROUND('⚙ Config & Assumptions'!B5*'⚙ Config & Assumptions'!B13*'⚙ Config & Assumptions'!B21,0) -> 17478 | AB12: =IF(AA12="","",AA12-Z12) | AC12: =IF(OR(AA12="",Z12=0),"",(AA12-Z12)/Z12) | AD12: =ROUND('⚙ Config & Assumptions'!B5*'⚙ Config & Assumptions'!B14*'⚙ Config & Assumptions'!B21,0) -> 16604 | AF12: =IF(AE12="","",AE12-AD12) | AG12: =IF(OR(AE12="",AD12=0),"",(AE12-AD12)/AD12) | AH12: =ROUND('⚙ Config & Assumptions'!B5*'⚙ Config & Assumptions'!B15*'⚙ Config & Assumptions'!B21,0) -> 15731 | AJ12: =IF(AI12="","",AI12-AH12) | AK12: =IF(OR(AI12="",AH12=0),"",(AI12-AH12)/AH12) | AL12: =ROUND('⚙ Config & Assumptions'!B5*'⚙ Config & Assumptions'!B16*'⚙ Config & Assumptions'!B21,0) -> 15731 | AN12: =IF(AM12="","",AM12-AL12) | AO12: =IF(OR(AM12="",AL12=0),"",(AM12-AL12)/AL12) | AP12: =ROUND('⚙ Config & Assumptions'!B5*'⚙ Config & Assumptions'!B17*'⚙ Config & Assumptions'!B21,0) -> 14857 | AR12: =IF(AQ12="","",AQ12-AP12) | AS12: =IF(OR(AQ12="",AP12=0),"",(AQ12-AP12)/AP12) | AT12: =ROUND('⚙ Config & Assumptions'!B5*'⚙ Config & Assumptions'!B18*'⚙ Config & Assumptions'!B21,0) -> 12235 | AV12: =IF(AU12="","",AU12-AT12) | AW12: =IF(OR(AU12="",AT12=0),"",(AU12-AT12)/AT12) | AX12: =CHOOSE('⚙ Config & Assumptions'!B41,B12,F12,J12,N12,R12,V12,Z12,AD12,AH12,AL12,AP12,AT12) -> 12235 | AY12: =IF(CHOOSE('⚙ Config & Assumptions'!B41,C12,G12,K12,O12,S12,W12,AA12,AE12,AI12,AM12,AQ12,AU12)="","",CHOOSE('⚙ Config & Assumptions'!B41,C12,G12,K12,O12,S12,W12,AA12,AE12,AI12,AM12,AQ12,AU12)) | AZ12: =IF(AY12="","",AY12-AX12) | BA12: =IF(OR(AY12="",AX12=0),"",(AY12-AX12)/AX12) | BB12: =IF('⚙ Config & Assumptions'!B41>=1,B12,0)+IF('⚙ Config & Assumptions'!B41>=2,F12,0)+IF('⚙ Config & Assumptions'!B41>=3,J12,0)+IF('⚙ Config & Assumptions'!B41>=4,N12,0)+IF('⚙ Config & Assumptions'!B41>=5,R12,0)+IF('⚙ Config & Assumptions'!B41>=6,V12,0)+IF('⚙ Config & Assumptions'!B41>=7,Z12,0)+IF('⚙ Config & Assumptions'!B41>=8,AD12,0)+IF('⚙ Config & Assumptions'!B41>=9,AH12,0)+IF('⚙ Config & Assumptions'!B41>=10,AL12,0)+IF('⚙ Config & Assumptions'!B41>=11,AP12,0)+IF('⚙ Config & Assumptions'!B41>=12,AT12,0) -> 12235 | BC12: =IF(AND('⚙ Config & Assumptions'!B41>=1,C12<>""),C12,0)+IF(AND('⚙ Config & Assumptions'!B41>=2,G12<>""),G12,0)+IF(AND('⚙ Config & Assumptions'!B41>=3,K12<>""),K12,0)+IF(AND('⚙ Config & Assumptions'!B41>=4,O12<>""),O12,0)+IF(AND('⚙ Config & Assumptions'!B41>=5,S12<>""),S12,0)+IF(AND('⚙ Config & Assumptions'!B41>=6,W12<>""),W12,0)+IF(AND('⚙ Config & Assumptions'!B41>=7,AA12<>""),AA12,0)+IF(AND('⚙ Config & Assumptions'!B41>=8,AE12<>""),AE12,0)+IF(AND('⚙ Config & Assumptions'!B41>=9,AI12<>""),AI12,0)+IF(AND('⚙ Config & Assumptions'!B41>=10,AM12<>""),AM12,0)+IF(AND('⚙ Config & Assumptions'!B41>=11,AQ12<>""),AQ12,0)+IF(AND('⚙ Config & Assumptions'!B41>=12,AU12<>""),AU12,0) -> 0 | BD12: =IF(BC12=0,"",BC12-BB12) | BE12: =IF(OR(BC12=0,BB12=0),"",(BC12-BB12)/BB12)
A13: (-) Returns & Refunds (₹) | B13: =ROUND('⚙ Config & Assumptions'!B5*'⚙ Config & Assumptions'!B7*'⚙ Config & Assumptions'!B22*'⚙ Config & Assumptions'!B21,0) -> 970 | D13: =IF(C13="","",C13-B13) | E13: =IF(OR(C13="",B13=0),"",(C13-B13)/B13) | F13: =ROUND('⚙ Config & Assumptions'!B5*'⚙ Config & Assumptions'!B8*'⚙ Config & Assumptions'!B22*'⚙ Config & Assumptions'!B21,0) -> 1040 | H13: =IF(G13="","",G13-F13) | I13: =IF(OR(G13="",F13=0),"",(G13-F13)/F13) | J13: =ROUND('⚙ Config & Assumptions'!B5*'⚙ Config & Assumptions'!B9*'⚙ Config & Assumptions'!B22*'⚙ Config & Assumptions'!B21,0) -> 901 | L13: =IF(K13="","",K13-J13) | M13: =IF(OR(K13="",J13=0),"",(K13-J13)/J13) | N13: =ROUND('⚙ Config & Assumptions'!B5*'⚙ Config & Assumptions'!B10*'⚙ Config & Assumptions'!B22*'⚙ Config & Assumptions'!B21,0) -> 1040 | P13: =IF(O13="","",O13-N13) | Q13: =IF(OR(O13="",N13=0),"",(O13-N13)/N13) | R13: =ROUND('⚙ Config & Assumptions'!B5*'⚙ Config & Assumptions'!B11*'⚙ Config & Assumptions'!B22*'⚙ Config & Assumptions'!B21,0) -> 1247 | T13: =IF(S13="","",S13-R13) | U13: =IF(OR(S13="",R13=0),"",(S13-R13)/R13) | V13: =ROUND('⚙ Config & Assumptions'!B5*'⚙ Config & Assumptions'!B12*'⚙ Config & Assumptions'!B22*'⚙ Config & Assumptions'!B21,0) -> 1317 | X13: =IF(W13="","",W13-V13) | Y13: =IF(OR(W13="",V13=0),"",(W13-V13)/V13) | Z13: =ROUND('⚙ Config & Assumptions'!B5*'⚙ Config & Assumptions'!B13*'⚙ Config & Assumptions'!B22*'⚙ Config & Assumptions'!B21,0) -> 1386 | AB13: =IF(AA13="","",AA13-Z13) | AC13: =IF(OR(AA13="",Z13=0),"",(AA13-Z13)/Z13) | AD13: =ROUND('⚙ Config & Assumptions'!B5*'⚙ Config & Assumptions'!B14*'⚙ Config & Assumptions'!B22*'⚙ Config & Assumptions'!B21,0) -> 1317 | AF13: =IF(AE13="","",AE13-AD13) | AG13: =IF(OR(AE13="",AD13=0),"",(AE13-AD13)/AD13) | AH13: =ROUND('⚙ Config & Assumptions'!B5*'⚙ Config & Assumptions'!B15*'⚙ Config & Assumptions'!B22*'⚙ Config & Assumptions'!B21,0) -> 1247 | AJ13: =IF(AI13="","",AI13-AH13) | AK13: =IF(OR(AI13="",AH13=0),"",(AI13-AH13)/AH13) | AL13: =ROUND('⚙ Config & Assumptions'!B5*'⚙ Config & Assumptions'!B16*'⚙ Config & Assumptions'!B22*'⚙ Config & Assumptions'!B21,0) -> 1247 | AN13: =IF(AM13="","",AM13-AL13) | AO13: =IF(OR(AM13="",AL13=0),"",(AM13-AL13)/AL13) | AP13: =ROUND('⚙ Config & Assumptions'!B5*'⚙ Config & Assumptions'!B17*'⚙ Config & Assumptions'!B22*'⚙ Config & Assumptions'!B21,0) -> 1178 | AR13: =IF(AQ13="","",AQ13-AP13) | AS13: =IF(OR(AQ13="",AP13=0),"",(AQ13-AP13)/AP13) | AT13: =ROUND('⚙ Config & Assumptions'!B5*'⚙ Config & Assumptions'!B18*'⚙ Config & Assumptions'!B22*'⚙ Config & Assumptions'!B21,0) -> 970 | AV13: =IF(AU13="","",AU13-AT13) | AW13: =IF(OR(AU13="",AT13=0),"",(AU13-AT13)/AT13) | AX13: =CHOOSE('⚙ Config & Assumptions'!B41,B13,F13,J13,N13,R13,V13,Z13,AD13,AH13,AL13,AP13,AT13) -> 970 | AY13: =IF(CHOOSE('⚙ Config & Assumptions'!B41,C13,G13,K13,O13,S13,W13,AA13,AE13,AI13,AM13,AQ13,AU13)="","",CHOOSE('⚙ Config & Assumptions'!B41,C13,G13,K13,O13,S13,W13,AA13,AE13,AI13,AM13,AQ13,AU13)) | AZ13: =IF(AY13="","",AY13-AX13) | BA13: =IF(OR(AY13="",AX13=0),"",(AY13-AX13)/AX13) | BB13: =IF('⚙ Config & Assumptions'!B41>=1,B13,0)+IF('⚙ Config & Assumptions'!B41>=2,F13,0)+IF('⚙ Config & Assumptions'!B41>=3,J13,0)+IF('⚙ Config & Assumptions'!B41>=4,N13,0)+IF('⚙ Config & Assumptions'!B41>=5,R13,0)+IF('⚙ Config & Assumptions'!B41>=6,V13,0)+IF('⚙ Config & Assumptions'!B41>=7,Z13,0)+IF('⚙ Config & Assumptions'!B41>=8,AD13,0)+IF('⚙ Config & Assumptions'!B41>=9,AH13,0)+IF('⚙ Config & Assumptions'!B41>=10,AL13,0)+IF('⚙ Config & Assumptions'!B41>=11,AP13,0)+IF('⚙ Config & Assumptions'!B41>=12,AT13,0) -> 970 | BC13: =IF(AND('⚙ Config & Assumptions'!B41>=1,C13<>""),C13,0)+IF(AND('⚙ Config & Assumptions'!B41>=2,G13<>""),G13,0)+IF(AND('⚙ Config & Assumptions'!B41>=3,K13<>""),K13,0)+IF(AND('⚙ Config & Assumptions'!B41>=4,O13<>""),O13,0)+IF(AND('⚙ Config & Assumptions'!B41>=5,S13<>""),S13,0)+IF(AND('⚙ Config & Assumptions'!B41>=6,W13<>""),W13,0)+IF(AND('⚙ Config & Assumptions'!B41>=7,AA13<>""),AA13,0)+IF(AND('⚙ Config & Assumptions'!B41>=8,AE13<>""),AE13,0)+IF(AND('⚙ Config & Assumptions'!B41>=9,AI13<>""),AI13,0)+IF(AND('⚙ Config & Assumptions'!B41>=10,AM13<>""),AM13,0)+IF(AND('⚙ Config & Assumptions'!B41>=11,AQ13<>""),AQ13,0)+IF(AND('⚙ Config & Assumptions'!B41>=12,AU13<>""),AU13,0) -> 0 | BD13: =IF(BC13=0,"",BC13-BB13) | BE13: =IF(OR(BC13=0,BB13=0),"",(BC13-BB13)/BB13)
